Workbook

Sheet ReadMe

Sheet Email

Sheet Summary
C1: Q2 2025 Widget Inc. Overview
C2: All data as of 06/18/2026
B5: Q2 Current Volume | G5: Current Clients
B6: =GETPIVOTDATA("Vol",Forecast!$A$5,"Quarters (Date)",2,"Years (Date)",2025) -> #REF! | G6: =Forecast!$S$50 -> 50
B7: Prior Year | C7: % Change | G7: Prior Year | H7: % Change
B8: =GETPIVOTDATA("Vol",Forecast!$A$5,"Quarters (Date)",2,"Years (Date)",2024) -> #REF! | C8: =Forecast!Q12 -> 0.026742826 | G8: =Forecast!$O$50 -> 50 | H8: =G6/G8-1 -> 0
B27: Volume | K27: Q1YoY | N27: Q2YoY | Q27: H1 YoY
B28: Region | C28: Q1 2024 | D28: Q2 2024 | E28: Q3 2024 | F28: Q4 2024 | G28: Q1 2025 | H28: Q2 2025 | K28: # | L28: % | N28: # | O28: % | Q28: # | R28: %
B29: NAM | C29: =SUMIFS(Table2[Vol],Table2[Region Name],$B29,Table2[Quart],C$28) -> 509419 | D29: =SUMIFS(Table2[Vol],Table2[Region Name],$B29,Table2[Quart],D$28) -> 576618 | E29: =SUMIFS(Table2[Vol],Table2[Region Name],$B29,Table2[Quart],E$28) -> 363694 | F29: =SUMIFS(Table2[Vol],Table2[Region Name],$B29,Table2[Quart],F$28) -> 432034 | G29: =SUMIFS(Table2[Vol],Table2[Region Name],$B29,Table2[Quart],G$28) -> 530019 | H29: =SUMIFS(Table2[Vol],Table2[Region Name],$B29,Table2[Quart],H$28) -> 596502 | K29: =G29-C29 -> 20600 | L29: =(G29-C29)/C29 -> 0.040438225 | N29: =H29-D29 -> 19884 | O29: =(H29-D29)/D29 -> 0.034483835 | Q29: {=SUM(G29:H29-C29:D29)} -> 40484 | R29: {=(SUM(G29:H29-C29:D29)/SUM(C29:D29))} -> 0.037276815
B30: EMEA | C30: =SUMIFS(Table2[Vol],Table2[Region Name],$B30,Table2[Quart],C$28) -> 147852 | D30: =SUMIFS(Table2[Vol],Table2[Region Name],$B30,Table2[Quart],D$28) -> 173566 | E30: =SUMIFS(Table2[Vol],Table2[Region Name],$B30,Table2[Quart],E$28) -> 103536 | F30: =SUMIFS(Table2[Vol],Table2[Region Name],$B30,Table2[Quart],F$28) -> 129264 | G30: =SUMIFS(Table2[Vol],Table2[Region Name],$B30,Table2[Quart],G$28) -> 150204 | H30: =SUMIFS(Table2[Vol],Table2[Region Name],$B30,Table2[Quart],H$28) -> 176338 | K30: =G30-C30 -> 2352 | L30: =(G30-C30)/C30 -> 0.0159078 | N30: =H30-D30 -> 2772 | O30: =(H30-D30)/D30 -> 0.01597087 | Q30: {=SUM(G30:H30-C30:D30)} -> 5124 | R30: {=(SUM(G30:H30-C30:D30)/SUM(C30:D30))} -> 0.015941858
B31: APAC | C31: =SUMIFS(Table2[Vol],Table2[Region Name],$B31,Table2[Quart],C$28) -> 95736 | D31: =SUMIFS(Table2[Vol],Table2[Region Name],$B31,Table2[Quart],D$28) -> 107338 | E31: =SUMIFS(Table2[Vol],Table2[Region Name],$B31,Table2[Quart],E$28) -> 69198 | F31: =SUMIFS(Table2[Vol],Table2[Region Name],$B31,Table2[Quart],F$28) -> 80144 | G31: =SUMIFS(Table2[Vol],Table2[Region Name],$B31,Table2[Quart],G$28) -> 99778 | H31: =SUMIFS(Table2[Vol],Table2[Region Name],$B31,Table2[Quart],H$28) -> 109811 | K31: =G31-C31 -> 4042 | L31: =(G31-C31)/C31 -> 0.042220272 | N31: =H31-D31 -> 2473 | O31: =(H31-D31)/D31 -> 0.023039371 | Q31: {=SUM(G31:H31-C31:D31)} -> 6515 | R31: {=(SUM(G31:H31-C31:D31)/SUM(C31:D31))} -> 0.032081901
B32: LATAM | C32: =SUMIFS(Table2[Vol],Table2[Region Name],$B32,Table2[Quart],C$28) -> 69053 | D32: =SUMIFS(Table2[Vol],Table2[Region Name],$B32,Table2[Quart],D$28) -> 82618 | E32: =SUMIFS(Table2[Vol],Table2[Region Name],$B32,Table2[Quart],E$28) -> 50574 | F32: =SUMIFS(Table2[Vol],Table2[Region Name],$B32,Table2[Quart],F$28) -> 65121 | G32: =SUMIFS(Table2[Vol],Table2[Region Name],$B32,Table2[Quart],G$28) -> 75265 | H32: =SUMIFS(Table2[Vol],Table2[Region Name],$B32,Table2[Quart],H$28) -> 82631 | K32: =G32-C32 -> 6212 | L32: =(G32-C32)/C32 -> 0.089959886 | N32: =H32-D32 -> 13 | O32: =(H32-D32)/D32 -> 0.0001573507 | Q32: {=SUM(G32:H32-C32:D32)} -> 6225 | R32: {=(SUM(G32:H32-C32:D32)/SUM(C32:D32))} -> 0.041042783
B33: Total | C33: =SUM(C29:C32) -> 822060 | D33: =SUM(D29:D32) -> 940140 | E33: =SUM(E29:E32) -> 587002 | F33: =SUM(F29:F32) -> 706563 | G33: =SUM(G29:G32) -> 855266 | H33: =SUM(H29:H32) -> 965282 | K33: =SUM(K29:K32) -> 33206 | L33: =(G33-C33)/C33 -> 0.040393645 | N33: =H33-D33 -> 25142 | O33: =(H33-D33)/D33 -> 0.026742826 | Q33: =SUM(Q29:Q32) -> 58348 | R33: {=(SUM(G33:H33-C33:D33)/SUM(C33:D33))} -> 0.033110884
B35: Customers | K35: Q2YoY | N35: Q2YoY | Q35: H1 YoY
B36: Region | C36: Q1 2024 | D36: Q2 2024 | E36: Q3 2024 | F36: Q4 2024 | G36: Q1 2025 | H36: Q2 2025 | K36: # | L36: % | N36: # | O36: % | Q36: # | R36: %
B37: NAM | C37: =ROUNDUP(COUNTIFS(Table2[Region Name],$B37,Table2[Quart],C$36)/3,0) -> 18 | D37: =ROUNDUP(COUNTIFS(Table2[Region Name],$B37,Table2[Quart],D$36)/3,0) -> 19 | E37: =ROUNDUP(COUNTIFS(Table2[Region Name],$B37,Table2[Quart],E$36)/3,0) -> 19 | F37: =ROUNDUP(COUNTIFS(Table2[Region Name],$B37,Table2[Quart],F$36)/3,0) -> 20 | G37: =ROUNDUP(COUNTIFS(Table2[Region Name],$B37,Table2[Quart],G$36)/3,0) -> 20 | H37: =ROUNDUP(COUNTIFS(Table2[Region Name],$B37,Table2[Quart],H$36)/3,0) -> 20 | K37: =G37-C37 -> 2 | L37: =(G37-C37)/C37 -> 0.11111111 | N37: =H37-D37 -> 1 | O37: =(H37-D37)/D37 -> 0.052631579 | Q37: {=SUM(G37:H37-C37:D37)} -> 3 | R37: {=(SUM(G37:H37-C37:D37)/SUM(C37:D37))} -> 0.081081081
B38: EMEA | C38: =ROUNDUP(COUNTIFS(Table2[Region Name],$B38,Table2[Quart],C$36)/3,0) -> 8 | D38: =ROUNDUP(COUNTIFS(Table2[Region Name],$B38,Table2[Quart],D$36)/3,0) -> 8 | E38: =ROUNDUP(COUNTIFS(Table2[Region Name],$B38,Table2[Quart],E$36)/3,0) -> 8 | F38: =ROUNDUP(COUNTIFS(Table2[Region Name],$B38,Table2[Quart],F$36)/3,0) -> 8 | G38: =ROUNDUP(COUNTIFS(Table2[Region Name],$B38,Table2[Quart],G$36)/3,0) -> 8 | H38: =ROUNDUP(COUNTIFS(Table2[Region Name],$B38,Table2[Quart],H$36)/3,0) -> 8 | K38: =G38-C38 -> 0 | L38: =(G38-C38)/C38 -> 0 | N38: =H38-D38 -> 0 | O38: =(H38-D38)/D38 -> 0 | Q38: {=SUM(G38:H38-C38:D38)} -> 0 | R38: {=(SUM(G38:H38-C38:D38)/SUM(C38:D38))} -> 0
B39: APAC | C39: =ROUNDUP(COUNTIFS(Table2[Region Name],$B39,Table2[Quart],C$36)/3,0) -> 13 | D39: =ROUNDUP(COUNTIFS(Table2[Region Name],$B39,Table2[Quart],D$36)/3,0) -> 13 | E39: =ROUNDUP(COUNTIFS(Table2[Region Name],$B39,Table2[Quart],E$36)/3,0) -> 14 | F39: =ROUNDUP(COUNTIFS(Table2[Region Name],$B39,Table2[Quart],F$36)/3,0) -> 14 | G39: =ROUNDUP(COUNTIFS(Table2[Region Name],$B39,Table2[Quart],G$36)/3,0) -> 14 | H39: =ROUNDUP(COUNTIFS(Table2[Region Name],$B39,Table2[Quart],H$36)/3,0) -> 13 | K39: =G39-C39 -> 1 | L39: =(G39-C39)/C39 -> 0.076923077 | N39: =H39-D39 -> 0 | O39: =(H39-D39)/D39 -> 0 | Q39: {=SUM(G39:H39-C39:D39)} -> 1 | R39: {=(SUM(G39:H39-C39:D39)/SUM(C39:D39))} -> 0.038461538
B40: LATAM | C40: =ROUNDUP(COUNTIFS(Table2[Region Name],$B40,Table2[Quart],C$36)/3,0) -> 10 | D40: =ROUNDUP(COUNTIFS(Table2[Region Name],$B40,Table2[Quart],D$36)/3,0) -> 10 | E40: =ROUNDUP(COUNTIFS(Table2[Region Name],$B40,Table2[Quart],E$36)/3,0) -> 11 | F40: =ROUNDUP(COUNTIFS(Table2[Region Name],$B40,Table2[Quart],F$36)/3,0) -> 11 | G40: =ROUNDUP(COUNTIFS(Table2[Region Name],$B40,Table2[Quart],G$36)/3,0) -> 11 | H40: =ROUNDUP(COUNTIFS(Table2[Region Name],$B40,Table2[Quart],H$36)/3,0) -> 9 | K40: =G40-C40 -> 1 | L40: =(G40-C40)/C40 -> 0.1 | N40: =H40-D40 -> -1 | O40: =(H40-D40)/D40 -> -0.1 | Q40: {=SUM(G40:H40-C40:D40)} -> 0 | R40: {=(SUM(G40:H40-C40:D40)/SUM(C40:D40))} -> 0
B41: Total | C41: =SUM(C37:C40) -> 49 | D41: =SUM(D37:D40) -> 50 | E41: =SUM(E37:E40) -> 52 | F41: =SUM(F37:F40) -> 53 | G41: =SUM(G37:G40) -> 53 | H41: =SUM(H37:H40) -> 50 | K41: =G41-C41 -> 4 | L41: =(G41-C41)/C41 -> 0.081632653 | N41: =H41-D41 -> 0 | O41: =(H41-D41)/D41 -> 0 | Q41: =SUM(Q37:Q40) -> 4 | R41: {=(SUM(G41:H41-C41:D41)/SUM(C41:D41))} -> 0.04040404
B44: Average Volume / Customer | K44: Q2YoY | N44: Q2YoY | Q44: H1 YoY
B45: Region | C45: Q1 2024 | D45: Q2 2024 | E45: Q3 2024 | F45: Q4 2024 | G45: Q1 2025 | H45: Q2 2025 | K45: # | L45: % | N45: # | O45: % | Q45: # | R45: %
B46: NAM | C46: =C29/C37 -> 28301.056 | D46: =D29/D37 -> 30348.316 | E46: =E29/E37 -> 19141.789 | F46: =F29/F37 -> 21601.7 | G46: =G29/G37 -> 26500.95 | H46: =H29/H37 -> 29825.1 | K46: =G46-C46 -> -1800.1056 | L46: =(G46-C46)/C46 -> -0.063605598 | N46: =H46-D46 -> -523.21579 | O46: =(H46-D46)/D46 -> -0.017240357 | Q46: {=SUM(G46:H46-C46:D46)} -> -2323.3213 | R46: {=(SUM(G46:H46-C46:D46)/SUM(C46:D46))} -> -0.039613747
B47: EMEA | C47: =C30/C38 -> 18481.5 | D47: =D30/D38 -> 21695.75 | E47: =E30/E38 -> 12942 | F47: =F30/F38 -> 16158 | G47: =G30/G38 -> 18775.5 | H47: =H30/H38 -> 22042.25 | K47: =G47-C47 -> 294 | L47: =(G47-C47)/C47 -> 0.0159078 | N47: =H47-D47 -> 346.5 | O47: =(H47-D47)/D47 -> 0.01597087 | Q47: {=SUM(G47:H47-C47:D47)} -> 640.5 | R47: {=(SUM(G47:H47-C47:D47)/SUM(C47:D47))} -> 0.015941858
B48: APAC | C48: =C31/C39 -> 7364.3077 | D48: =D31/D39 -> 8256.7692 | E48: =E31/E39 -> 4942.7143 | F48: =F31/F39 -> 5724.5714 | G48: =G31/G39 -> 7127 | H48: =H31/H39 -> 8447 | K48: =G48-C48 -> -237.30769 | L48: =(G48-C48)/C48 -> -0.032224033 | N48: =H48-D48 -> 190.23077 | O48: =(H48-D48)/D48 -> 0.023039371 | Q48: {=SUM(G48:H48-C48:D48)} -> -47.076923 | R48: {=(SUM(G48:H48-C48:D48)/SUM(C48:D48))} -> -0.0030136797
B49: LATAM | C49: =C32/C40 -> 6905.3 | D49: =D32/D40 -> 8261.8 | E49: =E32/E40 -> 4597.6364 | F49: =F32/F40 -> 5920.0909 | G49: =G32/G40 -> 6842.2727 | H49: =H32/H40 -> 9181.2222 | K49: =G49-C49 -> -63.027273 | L49: =(G49-C49)/C49 -> -0.0091273765 | N49: =H49-D49 -> 919.42222 | O49: =(H49-D49)/D49 -> 0.11128595 | Q49: {=SUM(G49:H49-C49:D49)} -> 856.39495 | R49: {=(SUM(G49:H49-C49:D49)/SUM(C49:D49))} -> 0.056463988
B50: Total | C50: =C33/C41 -> 16776.735 | D50: =D33/D41 -> 18802.8 | E50: =E33/E41 -> 11288.5 | F50: =F33/F41 -> 13331.377 | G50: =G33/G41 -> 16137.094 | H50: =H33/H41 -> 19305.64 | K50: =G50-C50 -> -639.64035 | L50: =(G50-C50)/C50 -> -0.03812663 | N50: =H50-D50 -> 502.84 | O50: =(H50-D50)/D50 -> 0.026742826 | Q50: =SUM(Q46:Q49) -> -873.50332 | R50: {=(SUM(G50:H50-C50:D50)/SUM(C50:D50))} -> -0.0038449169
C54: Key Notes
C55: Q2 Year Over Year growth slowed from slowed from Q1 growth of 4% down to 2.7%.
C56: 7k volume, or 55% of decline from loss of two customers in LATAM driving overall growth for region down from 9% in Q1 to flat in Q2 yoy
C57: NAM client onboarding in Q2 2024 had his/her first anniversary in Q2 2025, slowing perceived growth.

Sheet Forecast
A1: `
A5: Sum of Vol | B5: Years (Date) | C5: Quarters (Date) | D5: Date
B6: 2024 | F6: 2024 Total | G6: 2025 | I6: 2025 Total | M6: Q1 YoY | P6: Q2YoY | S6: Forcast Q2 | Y6: Q2YoY | AB6: Forcast Q2
B7: Qtr1 | C7: Qtr2 | D7: Qtr3 | E7: Qtr4 | G7: Qtr1 | H7: Qtr2 | M7: # | N7: % | P7: # | Q7: % | Y7: # | Z7: %
A8: Region Name | M8: =G9-B9 -> 20600 | N8: =(G9-B9)/B9 -> 0.040438225 | P8: =H9-C9 -> 19884 | Q8: =(H9-C9)/C9 -> 0.034483835 | S8: =C9*(1+N8) -> 599935.41 | T8: =S8/$S$12 -> 0.61335834 | Y8: =G25-C25 -> 3259 | Z8: =(G25-C25)/C25 -> 0.034250102 | AB8: =C25/(1-W8) -> 95153 | AC8: =AB8/$AB$12 -> 1.8460897 | AD8: =AB8-G25 -> -3259 | AE8: =AD8/$AD$12 -> 4.5076072
A9: NAM | B9: 509419 | C9: 576618 | D9: 363694 | E9: 432034 | F9: 1881765 | G9: 530019 | H9: 596502 | I9: 1126521 | M9: =G10-B10 -> 2352 | N9: =(G10-B10)/B10 -> 0.0159078 | P9: =H10-C10 -> 2772 | Q9: =(H10-C10)/C10 -> 0.01597087 | S9: =C10*(1+N9) -> 176327.05 | T9: =S9/$S$12 -> 0.18027219 | Y9: =G26-C26 -> 2022 | Z9: =(G26-C26)/C26 -> 0.023181693 | AB9: =C26/(1-W9) -> 87224 | AC9: =AB9/$AB$12 -> 1.692257 | AD9: =AB9-G26 -> -2022 | AE9: =AD9/$AD$12 -> 2.7966805
A10: EMEA | B10: 147852 | C10: 173566 | D10: 103536 | E10: 129264 | F10: 554218 | G10: 150204 | H10: 176338 | I10: 326542 | M10: =G11-B11 -> 4042 | N10: =(G11-B11)/B11 -> 0.042220272 | P10: =H11-C11 -> 2473 | Q10: =(H11-C11)/C11 -> 0.023039371 | S10: =C11*(1+N10) -> 111869.84 | T10: =S10/$S$12 -> 0.11437281 | Y10: =G27-C27 -> 939 | Z10: =(G27-C27)/C27 -> 0.013643893 | AB10: =C27/(1-W10) -> 68822 | AC10: =AB10/$AB$12 -> 1.3352347 | AD10: =AB10-G27 -> -939 | AE10: =AD10/$AD$12 -> 1.2987552
A11: APAC | B11: 95736 | C11: 107338 | D11: 69198 | E11: 80144 | F11: 352416 | G11: 99778 | H11: 109811 | I11: 209589 | M11: =G12-B12 -> 6212 | N11: =(G12-B12)/B12 -> 0.089959886 | P11: =H12-C12 -> 13 | Q11: =(H12-C12)/C12 -> 0.0001573507 | S11: =C12*(1+N11) -> 90050.306 | T11: =S11/$S$12 -> 0.092065088 | Y11: =G28-C28 -> 1387 | Z11: =(G28-C28)/C28 -> 0.024183565 | AB11: =C28/(1-W11) -> 57353 | AC11: =AB11/$AB$12 -> 1.1127214 | AD11: =AB11-G28 -> -1387 | AE11: =AD11/$AD$12 -> 1.9183956
A12: LATAM | B12: 69053 | C12: 82618 | D12: 50574 | E12: 65121 | F12: 267366 | G12: 75265 | H12: 82631 | I12: 157896 | M12: =G13-B13 -> 33206 | N12: =(G13-B13)/B13 -> 0.040393645 | P12: =H13-C13 -> 25142 | Q12: =(H13-C13)/C13 -> 0.026742826 | S12: =C13*(1+N12) -> 978115.68 | T12: =S12/$S$12 -> 1 | Y12: =G29-C29 -> 723 | Z12: =(G29-C29)/C29 -> 0.014027123 | AB12: =C29/(1-W12) -> 51543 | AC12: =AB12/$AB$12 -> 1 | AD12: =AB12-G29 -> -723 | AE12: =AD12/$AD$12 -> 1
A13: Grand Total | B13: 822060 | C13: 940140 | D13: 587002 | E13: 706563 | F13: 3055765 | G13: 855266 | H13: 965282 | I13: 1820548
A20: Sum of Vol | C20: Years (Date) | D20: Quarters (Date) | E20: Months (Date) | F20: Date
C21: 2024 | D21: 2024 | E21: 2024 | F21: 2024 | G21: 2025 | H21: 2025 | I21: Grand Total
C22: Qtr1 | D22: Qtr2 | E22: Qtr3 | F22: Qtr4 | G22: Qtr1 | H22: Qtr2
A24: Region Name | B24: CLID
A25: NAM | B25: CL69323 | C25: 95153 | D25: 101946 | E25: 67976 | F25: 74763 | G25: 98412 | H25: 105213 | I25: 543463
A26: NAM | B26: CL97995 | C26: 87224 | D26: 93457 | E26: 62305 | F26: 68540 | G26: 89246 | H26: 94887 | I26: 495659
A27: NAM | B27: CL38496 | C27: 68822 | D27: 79019 | E27: 48434 | F27: 58625 | G27: 69761 | H27: 81839 | I27: 406500
A28: NAM | B28: CL31601 | C28: 57353 | D28: 65847 | E28: 40364 | F28: 48865 | G28: 58740 | H28: 67226 | I28: 338395
A29: NAM | B29: CL33189 | C29: 51543 | D29: 63438 | E29: 35691 | F29: 47581 | G29: 52266 | H29: 65834 | I29: 316353
A30: NAM | B30: CL22140 | C30: 47869 | D30: 58910 | E30: 33137 | F30: 44184 | G30: 49385 | H30: 60071 | I30: 293556
A31: NAM | B31: CL37714 | C31: 38242 | D31: 43900 | E31: 26910 | F31: 32575 | G31: 39302 | H31: 44111 | I31: 225040
A32: NAM | B32: CL61534 | C32: 20189 | D32: 20896 | E32: 14525 | F32: 15234 | G32: 20317 | H32: 21097 | I32: 112258
A33: NAM | B33: CL46663 | C33: 8078 | D33: 8367 | E33: 5826 | F33: 6094 | G33: 8296 | H33: 8401 | I33: 45062
A34: NAM | B34: CL57593 | C34: 5024 | D34: 5769 | E34: 3536 | F34: 4278 | G34: 5035 | H34: 5895 | I34: 29537
A35: NAM | B35: CL96680 | C35: 4798 | D35: 5696 | E35: 3354 | F35: 4261 | G35: 4844 | H35: 5860 | I35: 28813
A36: NAM | B36: CL79204 | C36: 4934 | D36: 5281 | E36: 3520 | F36: 3875 | G36: 5039 | H36: 5432 | I36: 28081
... A38: NAM | B38: CL52426 | C38: 3809 | D38: 4363 | E38: 2684 | F38: 3246 | G38: 3775 | H38: 4424 | I38: 22301
A39: NAM | B39: CL17270 | D39: 1342 | E39: 3824 | F39: 4213 | G39: 5531 | H39: 5817 | I39: 20727
A40: NAM | B40: CL13213 | C40: 3584 | D40: 3716 | E40: 2587 | F40: 2713 | G40: 3613 | H40: 3743 | I40: 19956
A41: NAM | B41: CL64939 | C41: 3673 | D41: 4216 | E41: 2588 | F41: 3131 | G41: 3759 | H41: 1614 | I41: 18981
A42: NAM | B42: CL50297 | C42: 2680 | D42: 2873 | E42: 1919 | F42: 2114 | G42: 2699 | H42: 2912 | I42: 15197
A43: NAM | B43: CL94846 | C43: 1911 | D43: 2194 | E43: 1347 | F43: 1631 | G43: 1911 | H43: 2214 | I43: 11208
A44: NAM | B44: CL50651 | F44: 2092 | G44: 3465 | H44: 4321 | I44: 9878 | N44: 2024 | O44: 2024 | P44: 2024 | Q44: 2024 | R44: 2025 | S44: 2025
A45: EMEA | B45: CL87299 | C45: 73638 | D45: 90624 | E45: 50984 | F45: 67962 | G45: 74564 | H45: 91867 | I45: 449639 | N45: Qtr1 | O45: Qtr2 | P45: Qtr3 | Q45: Qtr4 | R45: Qtr1 | S45: Qtr2
A46: EMEA | B46: CL75562 | C46: 62302 | D46: 69102 | E46: 44184 | F46: 50976 | G46: 63613 | H46: 71175 | I46: 361352 | M46: NAM | N46: =COUNTIFS(C25:C82,">0",$A25:$A82,$M46) -> 18 | O46: =COUNTIFS(D25:D82,">0",$A25:$A82,$M46) -> 19 | P46: =COUNTIFS(E25:E82,">0",$A25:$A82,$M46) -> 19 | Q46: =COUNTIFS(F25:F82,">0",$A25:$A82,$M46) -> 20 | R46: =COUNTIFS(G25:G82,">0",$A25:$A82,$M46) -> 20 | S46: =COUNTIFS(H25:H82,">0",$A25:$A82,$M46) -> 20
A47: EMEA | B47: CL90358 | C47: 3264 | D47: 3740 | E47: 2301 | F47: 2784 | G47: 3295 | H47: 3738 | I47: 19122 | M47: EMEA | N47: =COUNTIFS(C26:C83,">0",$A26:$A83,$M47) -> 8 | O47: =COUNTIFS(D26:D83,">0",$A26:$A83,$M47) -> 8 | P47: =COUNTIFS(E26:E83,">0",$A26:$A83,$M47) -> 8 | Q47: =COUNTIFS(F26:F83,">0",$A26:$A83,$M47) -> 8 | R47: =COUNTIFS(G26:G83,">0",$A26:$A83,$M47) -> 8 | S47: =COUNTIFS(H26:H83,">0",$A26:$A83,$M47) -> 8
A48: EMEA | B48: CL71409 | C48: 3070 | D48: 3648 | E48: 2149 | F48: 2719 | G48: 3086 | H48: 3722 | I48: 18394 | M48: APAC | N48: =COUNTIFS(C27:C84,">0",$A27:$A84,$M48) -> 13 | O48: =COUNTIFS(D27:D84,">0",$A27:$A84,$M48) -> 13 | P48: =COUNTIFS(E27:E84,">0",$A27:$A84,$M48) -> 14 | Q48: =COUNTIFS(F27:F84,">0",$A27:$A84,$M48) -> 14 | R48: =COUNTIFS(G27:G84,">0",$A27:$A84,$M48) -> 14 | S48: =COUNTIFS(H27:H84,">0",$A27:$A84,$M48) -> 13
A49: EMEA | B49: CL13257 | C49: 1974 | D49: 2425 | E49: 1362 | F49: 1821 | G49: 1992 | H49: 1737 | I49: 11311 | M49: LATAM | N49: =COUNTIFS(C28:C85,">0",$A28:$A85,$M49) -> 10 | O49: =COUNTIFS(D28:D85,">0",$A28:$A85,$M49) -> 10 | P49: =COUNTIFS(E28:E85,">0",$A28:$A85,$M49) -> 11 | Q49: =COUNTIFS(F28:F85,">0",$A28:$A85,$M49) -> 11 | R49: =COUNTIFS(G28:G85,">0",$A28:$A85,$M49) -> 11 | S49: =COUNTIFS(H28:H85,">0",$A28:$A85,$M49) -> 9
A50: EMEA | B50: CL87149 | C50: 1877 | D50: 1932 | E50: 1352 | F50: 1420 | G50: 1891 | H50: 1943 | I50: 10415 | M50: Total | N50: =SUM(N46:N49) -> 49 | O50: =SUM(O46:O49) -> 50 | P50: =SUM(P46:P49) -> 52 | Q50: =SUM(Q46:Q49) -> 53 | R50: =SUM(R46:R49) -> 53 | S50: =SUM(S46:S49) -> 50
A51: EMEA | B51: CL29380 | C51: 1442 | D51: 1773 | E51: 1008 | F51: 1337 | G51: 1483 | H51: 1826 | I51: 8869
...

Sheet Pivot
A3: Sum of Vol | B3: Column Labels
A4: Row Labels | B4: NAM | C4: EMEA | D4: APAC | E4: LATAM
A5: 2024
A6: Qtr1 | B6: 509419 | C6: 147852 | D6: 95736 | E6: 69053
A7: Qtr2 | B7: 576618 | C7: 173566 | D7: 107338 | E7: 82618
A8: Qtr3 | B8: 363694 | C8: 103536 | D8: 69198 | E8: 50574
A9: Qtr4 | B9: 432034 | C9: 129264 | D9: 80144 | E9: 65121
A10: 2025
A11: Qtr1 | B11: 530019 | C11: 150204 | D11: 99778 | E11: 75265
A12: Qtr2 | B12: 596502 | C12: 176338 | D12: 109811 | E12: 82631
A13: Grand Total | B13: 3008286 | C13: 880760 | D13: 562005 | E13: 425262
A37: Sum of Vol | B37: Column Labels
B38: Qtr1 | D38: Qtr2 | F38: Qtr3 | G38: Qtr4 | I38: Q1 YoY | K38: Q2 YoY
A39: Row Labels | B39: 2024 | C39: 2025 | D39: 2024 | E39: 2025 | F39: 2024 | G39: 2024 | I39: # | J39: % | K39: # | L39: %
A40: NAM | B40: 509419 | C40: 530019 | D40: 576618 | E40: 596502 | F40: 363694 | G40: 432034 | I40: {=f} -> #NAME?
A41: EMEA | B41: 147852 | C41: 150204 | D41: 173566 | E41: 176338 | F41: 103536 | G41: 129264
A42: APAC | B42: 95736 | C42: 99778 | D42: 107338 | E42: 109811 | F42: 69198 | G42: 80144
A43: LATAM | B43: 69053 | C43: 75265 | D43: 82618 | E43: 82631 | F43: 50574 | G43: 65121
A44: Grand Total | B44: 822060 | C44: 855266 | D44: 940140 | E44: 965282 | F44: 587002 | G44: 706563

Sheet Volume Data
A1: CLID | B1: Date | C1: Vol | D1: LEN | E1: Xlookup Region ID | F1: Index Region ID | G1: Region Name | H1: Quart | I1: Quarter by Vlookup | N1: Date Start | O1: Date End | P1: name
A2: CL11420 | B2: 45382 | C2: 884 | D2: =LEN(Table2[[#This Row],[CLID]]) -> 7 | E2: =_xlfn.XLOOKUP('Volume Data'!A:A,'Geo Data'!D:D,'Geo Data'!B:B) -> GEO1004 | F2: =INDEX(GeoByClient[GEOID],MATCH(Table2[[#This Row],[CLID]],GeoByClient[Right],0)) -> GEO1004 | G2: =_xlfn.XLOOKUP(Table2[[#This Row],[Xlookup Region ID]],GEONames[GEOID],GEONames[GEO Name]) -> LATAM | H2: ="Q"&ROUNDUP(MONTH(Table2[[#This Row],[Date]])/3,0)&" "&YEAR(Table2[[#This Row],[Date]]) -> Q1 2024 | I2: =VLOOKUP(Table2[[#This Row],[Date]],Table7[],3) -> Q1 2024 | N2: 45292 | O2: 45382 | P2: Q1 2024
A3: CL11420 | B3: 45412 | C3: 886 | D3: =LEN(Table2[[#This Row],[CLID]]) -> 7 | E3: =_xlfn.XLOOKUP('Volume Data'!A:A,'Geo Data'!D:D,'Geo Data'!B:B) -> GEO1004 | F3: =INDEX(GeoByClient[GEOID],MATCH(Table2[[#This Row],[CLID]],GeoByClient[Right],0)) -> GEO1004 | G3: =_xlfn.XLOOKUP(Table2[[#This Row],[Xlookup Region ID]],GEONames[GEOID],GEONames[GEO Name]) -> LATAM | H3: ="Q"&ROUNDUP(MONTH(Table2[[#This Row],[Date]])/3,0)&" "&YEAR(Table2[[#This Row],[Date]]) -> Q2 2024 | I3: =VLOOKUP(Table2[[#This Row],[Date]],Table7[],3) -> Q2 2024 | N3: =O2+1 -> 45383 | O3: 45473 | P3: Q2 2024
A4: CL11420 | B4: 45443 | C4: 968 | D4: =LEN(Table2[[#This Row],[CLID]]) -> 7 | E4: =_xlfn.XLOOKUP('Volume Data'!A:A,'Geo Data'!D:D,'Geo Data'!B:B) -> GEO1004 | F4: =INDEX(GeoByClient[GEOID],MATCH(Table2[[#This Row],[CLID]],GeoByClient[Right],0)) -> GEO1004 | G4: =_xlfn.XLOOKUP(Table2[[#This Row],[Xlookup Region ID]],GEONames[GEOID],GEONames[GEO Name]) -> LATAM | H4: ="Q"&ROUNDUP(MONTH(Table2[[#This Row],[Date]])/3,0)&" "&YEAR(Table2[[#This Row],[Date]]) -> Q2 2024 | I4: =VLOOKUP(Table2[[#This Row],[Date]],Table7[],3) -> Q2 2024 | N4: =O3+1 -> 45474 | O4: 45565 | P4: Q3 2024
A5: CL11420 | B5: 45473 | C5: 564 | D5: =LEN(Table2[[#This Row],[CLID]]) -> 7 | E5: =_xlfn.XLOOKUP('Volume Data'!A:A,'Geo Data'!D:D,'Geo Data'!B:B) -> GEO1004 | F5: =INDEX(GeoByClient[GEOID],MATCH(Table2[[#This Row],[CLID]],GeoByClient[Right],0)) -> GEO1004 | G5: =_xlfn.XLOOKUP(Table2[[#This Row],[Xlookup Region ID]],GEONames[GEOID],GEONames[GEO Name]) -> LATAM | H5: ="Q"&ROUNDUP(MONTH(Table2[[#This Row],[Date]])/3,0)&" "&YEAR(Table2[[#This Row],[Date]]) -> Q2 2024 | I5: =VLOOKUP(Table2[[#This Row],[Date]],Table7[],3) -> Q2 2024 | N5: =O4+1 -> 45566 | O5: 45747 | P5: Q4 2024
A6: CL11420 | B6: 45504 | C6: 648 | D6: =LEN(Table2[[#This Row],[CLID]]) -> 7 | E6: =_xlfn.XLOOKUP('Volume Data'!A:A,'Geo Data'!D:D,'Geo Data'!B:B) -> GEO1004 | F6: =INDEX(GeoByClient[GEOID],MATCH(Table2[[#This Row],[CLID]],GeoByClient[Right],0)) -> GEO1004 | G6: =_xlfn.XLOOKUP(Table2[[#This Row],[Xlookup Region ID]],GEONames[GEOID],GEONames[GEO Name]) -> LATAM | H6: ="Q"&ROUNDUP(MONTH(Table2[[#This Row],[Date]])/3,0)&" "&YEAR(Table2[[#This Row],[Date]]) -> Q3 2024 | I6: =VLOOKUP(Table2[[#This Row],[Date]],Table7[],3) -> Q3 2024 | N6: =O5+1 -> 45748 | O6: 45747 | P6: Q1 2025
A7: CL11420 | B7: 45535 | C7: 406 | D7: =LEN(Table2[[#This Row],[CLID]]) -> 7 | E7: =_xlfn.XLOOKUP('Volume Data'!A:A,'Geo Data'!D:D,'Geo Data'!B:B) -> GEO1004 | F7: =INDEX(GeoByClient[GEOID],MATCH(Table2[[#This Row],[CLID]],GeoByClient[Right],0)) -> GEO1004 | G7: =_xlfn.XLOOKUP(Table2[[#This Row],[Xlookup Region ID]],GEONames[GEOID],GEONames[GEO Name]) -> LATAM | H7: ="Q"&ROUNDUP(MONTH(Table2[[#This Row],[Date]])/3,0)&" "&YEAR(Table2[[#This Row],[Date]]) -> Q3 2024 | I7: =VLOOKUP(Table2[[#This Row],[Date]],Table7[],3) -> Q3 2024 | N7: =O6+1 -> 45748 | O7: 45838 | P7: Q2 2025
A8: CL11420 | B8: 45565 | C8: 569 | D8: =LEN(Table2[[#This Row],[CLID]]) -> 7 | E8: =_xlfn.XLOOKUP('Volume Data'!A:A,'Geo Data'!D:D,'Geo Data'!B:B) -> GEO1004 | F8: =INDEX(GeoByClient[GEOID],MATCH(Table2[[#This Row],[CLID]],GeoByClient[Right],0)) -> GEO1004 | G8: =_xlfn.XLOOKUP(Table2[[#This Row],[Xlookup Region ID]],GEONames[GEOID],GEONames[GEO Name]) -> LATAM | H8: ="Q"&ROUNDUP(MONTH(Table2[[#This Row],[Date]])/3,0)&" "&YEAR(Table2[[#This Row],[Date]]) -> Q3 2024 | I8: =VLOOKUP(Table2[[#This Row],[Date]],Table7[],3) -> Q3 2024
A9: CL11420 | B9: 45596 | C9: 487 | D9: =LEN(Table2[[#This Row],[CLID]]) -> 7 | E9: =_xlfn.XLOOKUP('Volume Data'!A:A,'Geo Data'!D:D,'Geo Data'!B:B) -> GEO1004 | F9: =INDEX(GeoByClient[GEOID],MATCH(Table2[[#This Row],[CLID]],GeoByClient[Right],0)) -> GEO1004 | G9: =_xlfn.XLOOKUP(Table2[[#This Row],[Xlookup Region ID]],GEONames[GEOID],GEONames[GEO Name]) -> LATAM | H9: ="Q"&ROUNDUP(MONTH(Table2[[#This Row],[Date]])/3,0)&" "&YEAR(Table2[[#This Row],[Date]]) -> Q4 2024 | I9: =VLOOKUP(Table2[[#This Row],[Date]],Table7[],3) -> Q4 2024
A10: CL11420 | B10: 45626 | C10: 729 | D10: =LEN(Table2[[#This Row],[CLID]]) -> 7 | E10: =_xlfn.XLOOKUP('Volume Data'!A:A,'Geo Data'!D:D,'Geo Data'!B:B) -> GEO1004 | F10: =INDEX(GeoByClient[GEOID],MATCH(Table2[[#This Row],[CLID]],GeoByClient[Right],0)) -> GEO1004 | G10: =_xlfn.XLOOKUP(Table2[[#This Row],[Xlookup Region ID]],GEONames[GEOID],GEONames[GEO Name]) -> LATAM | H10: ="Q"&ROUNDUP(MONTH(Table2[[#This Row],[Date]])/3,0)&" "&YEAR(Table2[[#This Row],[Date]]) -> Q4 2024 | I10: =VLOOKUP(Table2[[#This Row],[Date]],Table7[],3) -> Q4 2024
A11: CL11420 | B11: 45657 | C11: 565 | D11: =LEN(Table2[[#This Row],[CLID]]) -> 7 | E11: =_xlfn.XLOOKUP('Volume Data'!A:A,'Geo Data'!D:D,'Geo Data'!B:B) -> GEO1004 | F11: =INDEX(GeoByClient[GEOID],MATCH(Table2[[#This Row],[CLID]],GeoByClient[Right],0)) -> GEO1004 | G11: =_xlfn.XLOOKUP(Table2[[#This Row],[Xlookup Region ID]],GEONames[GEOID],GEONames[GEO Name]) -> LATAM | H11: ="Q"&ROUNDUP(MONTH(Table2[[#This Row],[Date]])/3,0)&" "&YEAR(Table2[[#This Row],[Date]]) -> Q4 2024 | I11: =VLOOKUP(Table2[[#This Row],[Date]],Table7[],3) -> Q4 2024
A12: CL11420 | B12: 45838 | C12: 561 | D12: =LEN(Table2[[#This Row],[CLID]]) -> 7 | E12: =_xlfn.XLOOKUP('Volume Data'!A:A,'Geo Data'!D:D,'Geo Data'!B:B) -> GEO1004 | F12: =INDEX(GeoByClient[GEOID],MATCH(Table2[[#This Row],[CLID]],GeoByClient[Right],0)) -> GEO1004 | G12: =_xlfn.XLOOKUP(Table2[[#This Row],[Xlookup Region ID]],GEONames[GEOID],GEONames[GEO Name]) -> LATAM | H12: ="Q"&ROUNDUP(MONTH(Table2[[#This Row],[Date]])/3,0)&" "&YEAR(Table2[[#This Row],[Date]]) -> Q2 2025 | I12: =VLOOKUP(Table2[[#This Row],[Date]],Table7[],3) -> Q2 2025
A13: CL11420 | B13: 45808 | C13: 1014 | D13: =LEN(Table2[[#This Row],[CLID]]) -> 7 | E13: =_xlfn.XLOOKUP('Volume Data'!A:A,'Geo Data'!D:D,'Geo Data'!B:B) -> GEO1004 | F13: =INDEX(GeoByClient[GEOID],MATCH(Table2[[#This Row],[CLID]],GeoByClient[Right],0)) -> GEO1004 | G13: =_xlfn.XLOOKUP(Table2[[#This Row],[Xlookup Region ID]],GEONames[GEOID],GEONames[GEO Name]) -> LATAM | H13: ="Q"&ROUNDUP(MONTH(Table2[[#This Row],[Date]])/3,0)&" "&YEAR(Table2[[#This Row],[Date]]) -> Q2 2025 | I13: =VLOOKUP(Table2[[#This Row],[Date]],Table7[],3) -> Q2 2025
A14: CL11420 | B14: 45777 | C14: 878 | D14: =LEN(Table2[[#This Row],[CLID]]) -> 7 | E14: =_xlfn.XLOOKUP('Volume Data'!A:A,'Geo Data'!D:D,'Geo Data'!B:B) -> GEO1004 | F14: =INDEX(GeoByClient[GEOID],MATCH(Table2[[#This Row],[CLID]],GeoByClient[Right],0)) -> GEO1004 | G14: =_xlfn.XLOOKUP(Table2[[#This Row],[Xlookup Region ID]],GEONames[GEOID],GEONames[GEO Name]) -> LATAM | H14: ="Q"&ROUNDUP(MONTH(Table2[[#This Row],[Date]])/3,0)&" "&YEAR(Table2[[#This Row],[Date]]) -> Q2 2025 | I14: =VLOOKUP(Table2[[#This Row],[Date]],Table7[],3) -> Q2 2025
A15: CL11420 | B15: 45747 | C15: 922 | D15: =LEN(Table2[[#This Row],[CLID]]) -> 7 | E15: =_xlfn.XLOOKUP('Volume Data'!A:A,'Geo Data'!D:D,'Geo Data'!B:B) -> GEO1004 | F15: =INDEX(GeoByClient[GEOID],MATCH(Table2[[#This Row],[CLID]],GeoByClient[Right],0)) -> GEO1004 | G15: =_xlfn.XLOOKUP(Table2[[#This Row],[Xlookup Region ID]],GEONames[GEOID],GEONames[GEO Name]) -> LATAM | H15: ="Q"&ROUNDUP(MONTH(Table2[[#This Row],[Date]])/3,0)&" "&YEAR(Table2[[#This Row],[Date]]) -> Q1 2025 | I15: =VLOOKUP(Table2[[#This Row],[Date]],Table7[],3) -> Q4 2024
A16: CL11420 | B16: 45716 | C16: 668 | D16: =LEN(Table2[[#This Row],[CLID]]) -> 7 | E16: =_xlfn.XLOOKUP('Volume Data'!A:A,'Geo Data'!D:D,'Geo Data'!B:B) -> GEO1004 | F16: =INDEX(GeoByClient[GEOID],MATCH(Table2[[#This Row],[CLID]],GeoByClient[Right],0)) -> GEO1004 | G16: =_xlfn.XLOOKUP(Table2[[#This Row],[Xlookup Region ID]],GEONames[GEOID],GEONames[GEO Name]) -> LATAM | H16: ="Q"&ROUNDUP(MONTH(Table2[[#This Row],[Date]])/3,0)&" "&YEAR(Table2[[#This Row],[Date]]) -> Q1 2025 | I16: =VLOOKUP(Table2[[#This Row],[Date]],Table7[],3) -> Q4 2024
A17: CL11420 | B17: 45688 | C17: 725 | D17: =LEN(Table2[[#This Row],[CLID]]) -> 7 | E17: =_xlfn.XLOOKUP('Volume Data'!A:A,'Geo Data'!D:D,'Geo Data'!B:B) -> GEO1004 | F17: =INDEX(GeoByClient[GEOID],MATCH(Table2[[#This Row],[CLID]],GeoByClient[Right],0)) -> GEO1004 | G17: =_xlfn.XLOOKUP(Table2[[#This Row],[Xlookup Region ID]],GEONames[GEOID],GEONames[GEO Name]) -> LATAM | H17: ="Q"&ROUNDUP(MONTH(Table2[[#This Row],[Date]])/3,0)&" "&YEAR(Table2[[#This Row],[Date]]) -> Q1 2025 | I17: =VLOOKUP(Table2[[#This Row],[Date]],Table7[],3) -> Q4 2024
A18: CL13213 | B18: 45322 | C18: 1194 | D18: =LEN(Table2[[#This Row],[CLID]]) -> 7 | E18: =_xlfn.XLOOKUP('Volume Data'!A:A,'Geo Data'!D:D,'Geo Data'!B:B) -> GEO1001 | F18: =INDEX(GeoByClient[GEOID],MATCH(Table2[[#This Row],[CLID]],GeoByClient[Right],0)) -> GEO1001 | G18: =_xlfn.XLOOKUP(Table2[[#This Row],[Xlookup Region ID]],GEONames[GEOID],GEONames[GEO Name]) -> NAM | H18: ="Q"&ROUNDUP(MONTH(Table2[[#This Row],[Date]])/3,0)&" "&YEAR(Table2[[#This Row],[Date]]) -> Q1 2024 | I18: =VLOOKUP(Table2[[#This Row],[Date]],Table7[],3) -> Q1 2024
A19: CL13213 | B19: 45351 | C19: 942 | D19: =LEN(Table2[[#This Row],[CLID]]) -> 7 | E19: =_xlfn.XLOOKUP('Volume Data'!A:A,'Geo Data'!D:D,'Geo Data'!B:B) -> GEO1001 | F19: =INDEX(GeoByClient[GEOID],MATCH(Table2[[#This Row],[CLID]],GeoByClient[Right],0)) -> GEO1001 | G19: =_xlfn.XLOOKUP(Table2[[#This Row],[Xlookup Region ID]],GEONames[GEOID],GEONames[GEO Name]) -> NAM | H19: ="Q"&ROUNDUP(MONTH(Table2[[#This Row],[Date]])/3,0)&" "&YEAR(Table2[[#This Row],[Date]]) -> Q1 2024 | I19: =VLOOKUP(Table2[[#This Row],[Date]],Table7[],3) -> Q1 2024
... A908: CL99768 | B908: 45688 | C908: 222 | D908: =LEN(Table2[[#This Row],[CLID]]) -> 7 | E908: =_xlfn.XLOOKUP('Volume Data'!A:A,'Geo Data'!D:D,'Geo Data'!B:B) -> GEO1002 | F908: =INDEX(GeoByClient[GEOID],MATCH(Table2[[#This Row],[CLID]],GeoByClient[Right],0)) -> GEO1002 | G908: =_xlfn.XLOOKUP(Table2[[#This Row],[Xlookup Region ID]],GEONames[GEOID],GEONames[GEO Name]) -> APAC | H908: ="Q"&ROUNDUP(MONTH(Table2[[#This Row],[Date]])/3,0)&" "&YEAR(Table2[[#This Row],[Date]]) -> Q1 2025 | I908: =VLOOKUP(Table2[[#This Row],[Date]],Table7[],3) -> Q4 2024

Sheet EXT0070122021 (OG)
A1: CLID | B1: Date | C1: Vol
A2: CL11420 | B2: 03/31/2020 | C2: 884
B3: 04/30/2020 | C3: 886
B4: 05/31/2020 | C4: 968
B5: 06/30/2020 | C5: 564
B6: 07/31/2020 | C6: 648
B7: 08/31/2020 | C7: 406
B8: 09/30/2020 | C8: 569
B9: 10/31/2020 | C9: 487
B10: 11/30/2020 | C10: 729
B11: 12/31/2020 | C11: 565
B12: 06/30/2021 | C12: 561
B13: 05/31/2021 | C13: 1014
B14: 04/30/2021 | C14: 878
... B17: 01/31/2021 | C17: 725
A18: CL13213 | B18: 01/31/2020 | C18: 1194
B19: 02/29/2020 | C19: 942
B20: 03/31/2020 | C20: 1448
B21: 04/30/2020 | C21: 1323
B22: 05/31/2020 | C22: 1573
B23: 06/30/2020 | C23: 820
B24: 07/31/2020 | C24: 1069
B25: 08/31/2020 | C25: 571
B26: 09/30/2020 | C26: 947
B27: 10/31/2020 | C27: 694
B28: 11/30/2020 | C28: 1197
B29: 12/31/2020 | C29: 822
B30: 06/30/2021 | C30: 846
... B35: 01/31/2021 | C35: 1207
A36: CL13257 | B36: 01/31/2020 | C36: 532
B37: 02/29/2020 | C37: 760
B38: 03/31/2020 | C38: 682
B39: 04/30/2020 | C39: 984
B40: 05/31/2020 | C40: 760
B41: 06/30/2020 | C41: 681
B42: 07/31/2020 | C42: 457
B43: 08/31/2020 | C43: 528
B44: 09/30/2020 | C44: 377
B45: 10/31/2020 | C45: 606
B46: 11/30/2020 | C46: 534
...

Sheet Sheet3 (OG)
A1: CLID | B1: GEOID
A2: C-CL69323 | B2: GEO1001
A3: C-CL97995 | B3: GEO1001
A4: C-CL87299 | B4: GEO1003
A5: C-CL38496 | B5: GEO1001
A6: C-CL75562 | B6: GEO1003
A7: C-CL31601 | B7: GEO1001
A8: C-CL33189 | B8: GEO1001
A9: C-CL22140 | B9: GEO1001
A10: C-CL49960 | B10: GEO1002
A11: C-CL43946 | B11: GEO1004
A12: C-CL37714 | B12: GEO1001
... A54: C-CL82440 | B54: GEO1002

Sheet Geo Data
A1: CLID | B1: GEOID | C1: LEN | D1: Mid | E1: Right | H1: GEOID | I1: GEO Name | J1: Volume
A2: C-CL69323 | B2: GEO1001 | C2: =LEN(GeoByClient[[#This Row],[CLID]]) -> 9 | D2: =MID(GeoByClient[[#This Row],[CLID]],3,7) -> CL69323 | E2: =RIGHT(GeoByClient[[#This Row],[CLID]],7) -> CL69323 | H2: GEO1001 | I2: NAM | J2: =SUMIFS(Table2[Vol],Table2[Xlookup Region ID],GEONames[[#This Row],[GEOID]]) -> 3008286
A3: C-CL97995 | B3: GEO1001 | C3: =LEN(GeoByClient[[#This Row],[CLID]]) -> 9 | D3: =MID(GeoByClient[[#This Row],[CLID]],3,7) -> CL97995 | E3: =RIGHT(GeoByClient[[#This Row],[CLID]],7) -> CL97995 | H3: GEO1003 | I3: EMEA | J3: =SUMIFS(Table2[Vol],Table2[Xlookup Region ID],GEONames[[#This Row],[GEOID]]) -> 880760
A4: C-CL87299 | B4: GEO1003 | C4: =LEN(GeoByClient[[#This Row],[CLID]]) -> 9 | D4: =MID(GeoByClient[[#This Row],[CLID]],3,7) -> CL87299 | E4: =RIGHT(GeoByClient[[#This Row],[CLID]],7) -> CL87299 | H4: GEO1002 | I4: APAC | J4: =SUMIFS(Table2[Vol],Table2[Xlookup Region ID],GEONames[[#This Row],[GEOID]]) -> 562005
A5: C-CL38496 | B5: GEO1001 | C5: =LEN(GeoByClient[[#This Row],[CLID]]) -> 9 | D5: =MID(GeoByClient[[#This Row],[CLID]],3,7) -> CL38496 | E5: =RIGHT(GeoByClient[[#This Row],[CLID]],7) -> CL38496 | H5: GEO1004 | I5: LATAM | J5: =SUMIFS(Table2[Vol],Table2[Xlookup Region ID],GEONames[[#This Row],[GEOID]]) -> 425262
A6: C-CL75562 | B6: GEO1003 | C6: =LEN(GeoByClient[[#This Row],[CLID]]) -> 9 | D6: =MID(GeoByClient[[#This Row],[CLID]],3,7) -> CL75562 | E6: =RIGHT(GeoByClient[[#This Row],[CLID]],7) -> CL75562 | J6: =SUBTOTAL(109,GEONames[Volume]) -> 4876313
A7: C-CL31601 | B7: GEO1001 | C7: =LEN(GeoByClient[[#This Row],[CLID]]) -> 9 | D7: =MID(GeoByClient[[#This Row],[CLID]],3,7) -> CL31601 | E7: =RIGHT(GeoByClient[[#This Row],[CLID]],7) -> CL31601 | J7: =GEONames[[#Totals],[Volume]]-SUM(Table2[Vol]) -> 0
A8: C-CL33189 | B8: GEO1001 | C8: =LEN(GeoByClient[[#This Row],[CLID]]) -> 9 | D8: =MID(GeoByClient[[#This Row],[CLID]],3,7) -> CL33189 | E8: =RIGHT(GeoByClient[[#This Row],[CLID]],7) -> CL33189
A9: C-CL22140 | B9: GEO1001 | C9: =LEN(GeoByClient[[#This Row],[CLID]]) -> 9 | D9: =MID(GeoByClient[[#This Row],[CLID]],3,7) -> CL22140 | E9: =RIGHT(GeoByClient[[#This Row],[CLID]],7) -> CL22140
A10: C-CL49960 | B10: GEO1002 | C10: =LEN(GeoByClient[[#This Row],[CLID]]) -> 9 | D10: =MID(GeoByClient[[#This Row],[CLID]],3,7) -> CL49960 | E10: =RIGHT(GeoByClient[[#This Row],[CLID]],7) -> CL49960
A11: C-CL43946 | B11: GEO1004 | C11: =LEN(GeoByClient[[#This Row],[CLID]]) -> 9 | D11: =MID(GeoByClient[[#This Row],[CLID]],3,7) -> CL43946 | E11: =RIGHT(GeoByClient[[#This Row],[CLID]],7) -> CL43946
A12: C-CL37714 | B12: GEO1001 | C12: =LEN(GeoByClient[[#This Row],[CLID]]) -> 9 | D12: =MID(GeoByClient[[#This Row],[CLID]],3,7) -> CL37714 | E12: =RIGHT(GeoByClient[[#This Row],[CLID]],7) -> CL37714
A13: C-CL75274 | B13: GEO1002 | C13: =LEN(GeoByClient[[#This Row],[CLID]]) -> 9 | D13: =MID(GeoByClient[[#This Row],[CLID]],3,7) -> CL75274 | E13: =RIGHT(GeoByClient[[#This Row],[CLID]],7) -> CL75274
A14: C-CL61534 | B14: GEO1001 | C14: =LEN(GeoByClient[[#This Row],[CLID]]) -> 9 | D14: =MID(GeoByClient[[#This Row],[CLID]],3,7) -> CL61534 | E14: =RIGHT(GeoByClient[[#This Row],[CLID]],7) -> CL61534
A15: C-CL85641 | B15: GEO1004 | C15: =LEN(GeoByClient[[#This Row],[CLID]]) -> 9 | D15: =MID(GeoByClient[[#This Row],[CLID]],3,7) -> CL85641 | E15: =RIGHT(GeoByClient[[#This Row],[CLID]],7) -> CL85641
A16: C-CL46663 | B16: GEO1001 | C16: =LEN(GeoByClient[[#This Row],[CLID]]) -> 9 | D16: =MID(GeoByClient[[#This Row],[CLID]],3,7) -> CL46663 | E16: =RIGHT(GeoByClient[[#This Row],[CLID]],7) -> CL46663
A17: C-CL17270 | B17: GEO1001 | C17: =LEN(GeoByClient[[#This Row],[CLID]]) -> 9 | D17: =MID(GeoByClient[[#This Row],[CLID]],3,7) -> CL17270 | E17: =RIGHT(GeoByClient[[#This Row],[CLID]],7) -> CL17270
A18: C-CL57593 | B18: GEO1001 | C18: =LEN(GeoByClient[[#This Row],[CLID]]) -> 9 | D18: =MID(GeoByClient[[#This Row],[CLID]],3,7) -> CL57593 | E18: =RIGHT(GeoByClient[[#This Row],[CLID]],7) -> CL57593
A19: C-CL96680 | B19: GEO1001 | C19: =LEN(GeoByClient[[#This Row],[CLID]]) -> 9 | D19: =MID(GeoByClient[[#This Row],[CLID]],3,7) -> CL96680 | E19: =RIGHT(GeoByClient[[#This Row],[CLID]],7) -> CL96680
... A54: C-CL82440 | B54: GEO1002 | C54: =LEN(GeoByClient[[#This Row],[CLID]]) -> 9 | D54: =MID(GeoByClient[[#This Row],[CLID]],3,7) -> CL82440 | E54: =RIGHT(GeoByClient[[#This Row],[CLID]],7) -> CL82440

Sheet EXT0070122021 (OG) (2)
A1: CLID | B1: Date | C1: Vol | D1: Len
A2: CL11420 | B2: 43921 | C2: 884 | D2: =LEN(Table3[[#This Row],[CLID]]) -> 7
A3: CL11420 | B3: 43951 | C3: 886 | D3: =LEN(Table3[[#This Row],[CLID]]) -> 7
A4: CL11420 | B4: 43982 | C4: 968 | D4: =LEN(Table3[[#This Row],[CLID]]) -> 7
A5: CL11420 | B5: 44012 | C5: 564 | D5: =LEN(Table3[[#This Row],[CLID]]) -> 7
A6: CL11420 | B6: 44043 | C6: 648 | D6: =LEN(Table3[[#This Row],[CLID]]) -> 7
A7: CL11420 | B7: 44074 | C7: 406 | D7: =LEN(Table3[[#This Row],[CLID]]) -> 7
A8: CL11420 | B8: 44104 | C8: 569 | D8: =LEN(Table3[[#This Row],[CLID]]) -> 7
A9: CL11420 | B9: 44135 | C9: 487 | D9: =LEN(Table3[[#This Row],[CLID]]) -> 7
A10: CL11420 | B10: 44165 | C10: 729 | D10: =LEN(Table3[[#This Row],[CLID]]) -> 7
A11: CL11420 | B11: 44196 | C11: 565 | D11: =LEN(Table3[[#This Row],[CLID]]) -> 7
A12: CL11420 | B12: 44377 | C12: 561 | D12: =LEN(Table3[[#This Row],[CLID]]) -> 7
A13: CL11420 | B13: 44347 | C13: 1014 | D13: =LEN(Table3[[#This Row],[CLID]]) -> 7
... A908: CL99768 | B908: 44227 | C908: 222 | D908: =LEN(Table3[[#This Row],[CLID]]) -> 7
